2024-07-31 15:05:51,085 INFO: Mail configuration: SERVER=simmon.jp# 使用するメールサービスのSMTPサーバー, PORT=587, USE_TLS=True, USE_SSL=False [in c:\Users\2880\Desktop\forms\froms\app\__init__.py:63]
2024-07-31 15:05:51,582 INFO: Survey startup [in c:\Users\2880\Desktop\forms\froms\app\__init__.py:60]
2024-07-31 15:05:51,582 INFO: Mail configuration: SERVER=simmon.jp# 使用するメールサービスのSMTPサーバー, PORT=587, USE_TLS=True, USE_SSL=False [in c:\Users\2880\Desktop\forms\froms\app\__init__.py:63]
2024-07-31 15:05:51,582 INFO: Survey startup [in c:\Users\2880\Desktop\forms\froms\app\__init__.py:60]
2024-07-31 15:05:51,582 INFO: Survey startup [in c:\Users\2880\Desktop\forms\froms\app\__init__.py:60]
2024-07-31 15:05:51,582 INFO: Mail configuration: SERVER=simmon.jp# 使用するメールサービスのSMTPサーバー, PORT=587, USE_TLS=True, USE_SSL=False [in c:\Users\2880\Desktop\forms\froms\app\__init__.py:63]
2024-07-31 15:05:51,582 INFO: Mail configuration: SERVER=simmon.jp# 使用するメールサービスのSMTPサーバー, PORT=587, USE_TLS=True, USE_SSL=False [in c:\Users\2880\Desktop\forms\froms\app\__init__.py:63]
2024-07-31 15:06:22,491 ERROR: Failed to send email to saito_kouki@simmon.jp: [Errno 11001] getaddrinfo failed [in c:\Users\2880\Desktop\forms\froms\app\services\email_service.py:39]
Traceback (most recent call last):
  File "c:\Users\2880\Desktop\forms\froms\app\services\email_service.py", line 28, in send_email
    with smtplib.SMTP(smtp_server, current_app.config['MAIL_PORT']) as server:
         ^^^^^^^^^^^^^^^^^^^^^^^^^^^^^^^^^^^^^^^^^^^^^^^^^^^^^^^^^^
  File "C:\Users\2880\AppData\Local\Programs\Python\Python312\Lib\smtplib.py", line 255, in __init__
    (code, msg) = self.connect(host, port)
                  ^^^^^^^^^^^^^^^^^^^^^^^^
  File "C:\Users\2880\AppData\Local\Programs\Python\Python312\Lib\smtplib.py", line 341, in connect
    self.sock = self._get_socket(host, port, self.timeout)
                ^^^^^^^^^^^^^^^^^^^^^^^^^^^^^^^^^^^^^^^^^^
  File "C:\Users\2880\AppData\Local\Programs\Python\Python312\Lib\smtplib.py", line 312, in _get_socket
    return socket.create_connection((host, port), timeout,
           ^^^^^^^^^^^^^^^^^^^^^^^^^^^^^^^^^^^^^^^^^^^^^^^
  File "C:\Users\2880\AppData\Local\Programs\Python\Python312\Lib\socket.py", line 828, in create_connection
    for res in getaddrinfo(host, port, 0, SOCK_STREAM):
               ^^^^^^^^^^^^^^^^^^^^^^^^^^^^^^^^^^^^^^^
  File "C:\Users\2880\AppData\Local\Programs\Python\Python312\Lib\socket.py", line 963, in getaddrinfo
    for res in _socket.getaddrinfo(host, port, family, type, proto, flags):
               ^^^^^^^^^^^^^^^^^^^^^^^^^^^^^^^^^^^^^^^^^^^^^^^^^^^^^^^^^^^
socket.gaierror: [Errno 11001] getaddrinfo failed
2024-07-31 15:06:22,491 ERROR: Failed to send email to saito_kouki@simmon.jp: [Errno 11001] getaddrinfo failed [in c:\Users\2880\Desktop\forms\froms\app\services\email_service.py:39]
Traceback (most recent call last):
  File "c:\Users\2880\Desktop\forms\froms\app\services\email_service.py", line 28, in send_email
    with smtplib.SMTP(smtp_server, current_app.config['MAIL_PORT']) as server:
         ^^^^^^^^^^^^^^^^^^^^^^^^^^^^^^^^^^^^^^^^^^^^^^^^^^^^^^^^^^
  File "C:\Users\2880\AppData\Local\Programs\Python\Python312\Lib\smtplib.py", line 255, in __init__
    (code, msg) = self.connect(host, port)
                  ^^^^^^^^^^^^^^^^^^^^^^^^
  File "C:\Users\2880\AppData\Local\Programs\Python\Python312\Lib\smtplib.py", line 341, in connect
    self.sock = self._get_socket(host, port, self.timeout)
                ^^^^^^^^^^^^^^^^^^^^^^^^^^^^^^^^^^^^^^^^^^
  File "C:\Users\2880\AppData\Local\Programs\Python\Python312\Lib\smtplib.py", line 312, in _get_socket
    return socket.create_connection((host, port), timeout,
           ^^^^^^^^^^^^^^^^^^^^^^^^^^^^^^^^^^^^^^^^^^^^^^^
  File "C:\Users\2880\AppData\Local\Programs\Python\Python312\Lib\socket.py", line 828, in create_connection
    for res in getaddrinfo(host, port, 0, SOCK_STREAM):
               ^^^^^^^^^^^^^^^^^^^^^^^^^^^^^^^^^^^^^^^
  File "C:\Users\2880\AppData\Local\Programs\Python\Python312\Lib\socket.py", line 963, in getaddrinfo
    for res in _socket.getaddrinfo(host, port, family, type, proto, flags):
               ^^^^^^^^^^^^^^^^^^^^^^^^^^^^^^^^^^^^^^^^^^^^^^^^^^^^^^^^^^^
socket.gaierror: [Errno 11001] getaddrinfo failed
2024-07-31 15:07:41,420 INFO: Survey startup [in c:\Users\2880\Desktop\forms\froms\app\__init__.py:60]
2024-07-31 15:07:41,421 INFO: Mail configuration: SERVER=simmon.jp# 使用するメールサービスのSMTPサーバー, PORT=587, USE_TLS=True, USE_SSL=False [in c:\Users\2880\Desktop\forms\froms\app\__init__.py:63]
2024-07-31 15:07:41,423 INFO: Survey startup [in c:\Users\2880\Desktop\forms\froms\app\__init__.py:60]
2024-07-31 15:07:41,423 INFO: Survey startup [in c:\Users\2880\Desktop\forms\froms\app\__init__.py:60]
2024-07-31 15:07:41,423 INFO: Mail configuration: SERVER=simmon.jp# 使用するメールサービスのSMTPサーバー, PORT=587, USE_TLS=True, USE_SSL=False [in c:\Users\2880\Desktop\forms\froms\app\__init__.py:63]
2024-07-31 15:07:41,423 INFO: Mail configuration: SERVER=simmon.jp# 使用するメールサービスのSMTPサーバー, PORT=587, USE_TLS=True, USE_SSL=False [in c:\Users\2880\Desktop\forms\froms\app\__init__.py:63]
2024-07-31 15:08:58,980 ERROR: Failed to send email to saito_kouki@simmon.jp: [Errno 11001] getaddrinfo failed [in c:\Users\2880\Desktop\forms\froms\app\services\email_service.py:39]
Traceback (most recent call last):
  File "c:\Users\2880\Desktop\forms\froms\app\services\email_service.py", line 28, in send_email
    with smtplib.SMTP(smtp_server, current_app.config['MAIL_PORT']) as server:
         ^^^^^^^^^^^^^^^^^^^^^^^^^^^^^^^^^^^^^^^^^^^^^^^^^^^^^^^^^^
  File "C:\Users\2880\AppData\Local\Programs\Python\Python312\Lib\smtplib.py", line 255, in __init__
    (code, msg) = self.connect(host, port)
                  ^^^^^^^^^^^^^^^^^^^^^^^^
  File "C:\Users\2880\AppData\Local\Programs\Python\Python312\Lib\smtplib.py", line 341, in connect
    self.sock = self._get_socket(host, port, self.timeout)
                ^^^^^^^^^^^^^^^^^^^^^^^^^^^^^^^^^^^^^^^^^^
  File "C:\Users\2880\AppData\Local\Programs\Python\Python312\Lib\smtplib.py", line 312, in _get_socket
    return socket.create_connection((host, port), timeout,
           ^^^^^^^^^^^^^^^^^^^^^^^^^^^^^^^^^^^^^^^^^^^^^^^
  File "C:\Users\2880\AppData\Local\Programs\Python\Python312\Lib\socket.py", line 828, in create_connection
    for res in getaddrinfo(host, port, 0, SOCK_STREAM):
               ^^^^^^^^^^^^^^^^^^^^^^^^^^^^^^^^^^^^^^^
  File "C:\Users\2880\AppData\Local\Programs\Python\Python312\Lib\socket.py", line 963, in getaddrinfo
    for res in _socket.getaddrinfo(host, port, family, type, proto, flags):
               ^^^^^^^^^^^^^^^^^^^^^^^^^^^^^^^^^^^^^^^^^^^^^^^^^^^^^^^^^^^
socket.gaierror: [Errno 11001] getaddrinfo failed
2024-07-31 15:08:58,980 ERROR: Failed to send email to saito_kouki@simmon.jp: [Errno 11001] getaddrinfo failed [in c:\Users\2880\Desktop\forms\froms\app\services\email_service.py:39]
Traceback (most recent call last):
  File "c:\Users\2880\Desktop\forms\froms\app\services\email_service.py", line 28, in send_email
    with smtplib.SMTP(smtp_server, current_app.config['MAIL_PORT']) as server:
         ^^^^^^^^^^^^^^^^^^^^^^^^^^^^^^^^^^^^^^^^^^^^^^^^^^^^^^^^^^
  File "C:\Users\2880\AppData\Local\Programs\Python\Python312\Lib\smtplib.py", line 255, in __init__
    (code, msg) = self.connect(host, port)
                  ^^^^^^^^^^^^^^^^^^^^^^^^
  File "C:\Users\2880\AppData\Local\Programs\Python\Python312\Lib\smtplib.py", line 341, in connect
    self.sock = self._get_socket(host, port, self.timeout)
                ^^^^^^^^^^^^^^^^^^^^^^^^^^^^^^^^^^^^^^^^^^
  File "C:\Users\2880\AppData\Local\Programs\Python\Python312\Lib\smtplib.py", line 312, in _get_socket
    return socket.create_connection((host, port), timeout,
           ^^^^^^^^^^^^^^^^^^^^^^^^^^^^^^^^^^^^^^^^^^^^^^^
  File "C:\Users\2880\AppData\Local\Programs\Python\Python312\Lib\socket.py", line 828, in create_connection
    for res in getaddrinfo(host, port, 0, SOCK_STREAM):
               ^^^^^^^^^^^^^^^^^^^^^^^^^^^^^^^^^^^^^^^
  File "C:\Users\2880\AppData\Local\Programs\Python\Python312\Lib\socket.py", line 963, in getaddrinfo
    for res in _socket.getaddrinfo(host, port, family, type, proto, flags):
               ^^^^^^^^^^^^^^^^^^^^^^^^^^^^^^^^^^^^^^^^^^^^^^^^^^^^^^^^^^^
socket.gaierror: [Errno 11001] getaddrinfo failed
2024-07-31 15:09:56,404 INFO: Survey startup [in c:\Users\2880\Desktop\forms\froms\app\__init__.py:60]
2024-07-31 15:09:56,404 INFO: Mail configuration: SERVER=simmon.jp# 使用するメールサービスのSMTPサーバー, PORT=587, USE_TLS=True, USE_SSL=False [in c:\Users\2880\Desktop\forms\froms\app\__init__.py:63]
2024-07-31 15:09:56,407 INFO: Survey startup [in c:\Users\2880\Desktop\forms\froms\app\__init__.py:60]
2024-07-31 15:09:56,407 INFO: Survey startup [in c:\Users\2880\Desktop\forms\froms\app\__init__.py:60]
2024-07-31 15:09:56,408 INFO: Mail configuration: SERVER=simmon.jp# 使用するメールサービスのSMTPサーバー, PORT=587, USE_TLS=True, USE_SSL=False [in c:\Users\2880\Desktop\forms\froms\app\__init__.py:63]
2024-07-31 15:09:56,408 INFO: Mail configuration: SERVER=simmon.jp# 使用するメールサービスのSMTPサーバー, PORT=587, USE_TLS=True, USE_SSL=False [in c:\Users\2880\Desktop\forms\froms\app\__init__.py:63]
2024-07-31 15:12:22,355 INFO: Survey startup [in c:\Users\2880\Desktop\forms\froms\app\__init__.py:60]
2024-07-31 15:12:22,355 INFO: Mail configuration: SERVER=simmon.jp# 使用するメールサービスのSMTPサーバー, PORT=587, USE_TLS=True, USE_SSL=False [in c:\Users\2880\Desktop\forms\froms\app\__init__.py:63]
2024-07-31 15:12:22,358 INFO: Survey startup [in c:\Users\2880\Desktop\forms\froms\app\__init__.py:60]
2024-07-31 15:12:22,358 INFO: Survey startup [in c:\Users\2880\Desktop\forms\froms\app\__init__.py:60]
